const questions = [
  {
    id: 1,
    date: '15-08-2018',
    title: 'Tensorflow code not excecuting',
    body: 'The final response in the terminal is just "Process finished with exit code 0" I tried using multiple IDLE',
    answer: [
      {
        id: 1,
        reply: 'The error is telling you that the URL you have posted is not found. We can\'t tell you why it may be that it is not found without some of your code. Could you post a few snippets of relevant code so we can help you further',
      },
      {
        id: 2,
        reply: 'The error is telling you that the URL you have posted is not found. We so we can help you further?',
      },
    ],
  },
  {
    id: 2,
    date: '15-08-2018',
    title: 'Array not working with map() in React',
    body: 'How to use map() for array in Js, python, Angular etc',
    answer: [
      {
        id: 1,
        reply: 'Check MDN documentation about map(), reduce(), and filter()',
      },
      {
        id: 2,
        reply: 'Check other tag question the questions has been answer more than one',
      },
    ],

  },
  {
    id: 3,
    date: '15-05-2018',
    title: 'Why does a catch behalve like a resolve?',
    body: '',
    answer: [
      {
        id: 1,
        reply: 'You are catching the error, which means you intend to handle it. Since you don\'t again, your code assumes that you handled it in the appropriate way and it\'s no longer an error.',
      },
      {
        id: 2,
        reply: 'Do you need to pass error one level upper? Just rethrow error or throw brand new one.',
      },
    ],
  },

];

export default questions;
